<?xml version="1.0" encoding="utf-8"?>
<!-- This URDF was automatically created by SolidWorks to URDF Exporter! Originally created by Stephen Brawner (brawner@gmail.com) 
     Commit Version: 1.6.0-4-g7f85cfe  Build Version: 1.6.7995.38578
     For more information, please see http://wiki.ros.org/sw_urdf_exporter -->
<robot
  name="snake_tool">
  <link
    name="link_00">
    <visual>
      <origin
        xyz="0 0 0"
        rpy="0 0 0" />
      <geometry>
        <mesh
          filename="package://snake_description/meshes/link_00.STL" scale="0.001 0.001 0.001" />
      </geometry>
      <material
        name="">
        <color
          rgba="0.690196078431373 0.658823529411765 0.63921568627451 1" />
      </material>
    </visual>
    <collision>
      <origin
        xyz="0 0 0"
        rpy="0 0 0" />
      <geometry>
        <mesh
          filename="package://snake_description/meshes/link_00.STL" scale="0.001 0.001 0.001" />
      </geometry>
    </collision>
  </link>
  <link
    name="link_01">
    <visual>
      <origin
        xyz="0 0 0"
        rpy="0 0 0" />
      <geometry>
        <mesh
          filename="package://snake_description/meshes/link_01.STL" scale="0.001 0.001 0.001" />
      </geometry>
      <material
        name="">
        <color
          rgba="0.690196078431373 0.658823529411765 0.63921568627451 1" />
      </material>
    </visual>
    <collision>
      <origin
        xyz="0 0 0"
        rpy="0 0 0" />
      <geometry>
        <mesh
          filename="package://snake_description/meshes/link_01.STL" scale="0.001 0.001 0.001" />
      </geometry>
    </collision>
  </link>
  <joint
    name="joint_00"
    type="revolute">
    <origin
      xyz="0 0 0.0410297210859283"
      rpy="0 0 0" />
    <parent
      link="link_00" />
    <child
      link="link_01" />
    <axis
      xyz="0 1 0" />
    <limit
      lower="-0.16"
      upper="0.16"
      effort="0"
      velocity="0" />
  </joint>
  <link
    name="link_02">
    <visual>
      <origin
        xyz="0 0 0"
        rpy="0 0 0" />
      <geometry>
        <mesh
          filename="package://snake_description/meshes/link_02.STL" scale="0.001 0.001 0.001" />
      </geometry>
      <material
        name="">
        <color
          rgba="0.690196078431373 0.658823529411765 0.63921568627451 1" />
      </material>
    </visual>
    <collision>
      <origin
        xyz="0 0 0"
        rpy="0 0 0" />
      <geometry>
        <mesh
          filename="package://snake_description/meshes/link_02.STL" scale="0.001 0.001 0.001" />
      </geometry>
    </collision>
  </link>
  <joint
    name="joint_01"
    type="revolute">
    <origin
      xyz="0 0 0.00132488253734261"
      rpy="0 0 0" />
    <parent
      link="link_01" />
    <child
      link="link_02" />
    <axis
      xyz="0 1 0" />
    <limit
      lower="-0.16"
      upper="0.16"
      effort="0"
      velocity="0" />
  </joint>
  <link
    name="link_03">
    <visual>
      <origin
        xyz="0 0 0"
        rpy="0 0 0" />
      <geometry>
        <mesh
          filename="package://snake_description/meshes/link_03.STL" scale="0.001 0.001 0.001" />
      </geometry>
      <material
        name="">
        <color
          rgba="0.690196078431373 0.658823529411765 0.63921568627451 1" />
      </material>
    </visual>
    <collision>
      <origin
        xyz="0 0 0"
        rpy="0 0 0" />
      <geometry>
        <mesh
          filename="package://snake_description/meshes/link_03.STL" scale="0.001 0.001 0.001" />
      </geometry>
    </collision>
  </link>
  <joint
    name="joint_02"
    type="revolute">
    <origin
      xyz="0 0 0.00131520544017122"
      rpy="0 0 0" />
    <parent
      link="link_02" />
    <child
      link="link_03" />
    <axis
      xyz="0 1 0" />
    <limit
      lower="-0.16"
      upper="0.16"
      effort="0"
      velocity="0" />
  </joint>
  <link
    name="link_04">
    <visual>
      <origin
        xyz="0 0 0"
        rpy="0 0 0" />
      <geometry>
        <mesh
          filename="package://snake_description/meshes/link_04.STL" scale="0.001 0.001 0.001" />
      </geometry>
      <material
        name="">
        <color
          rgba="0.690196078431373 0.658823529411765 0.63921568627451 1" />
      </material>
    </visual>
    <collision>
      <origin
        xyz="0 0 0"
        rpy="0 0 0" />
      <geometry>
        <mesh
          filename="package://snake_description/meshes/link_04.STL" scale="0.001 0.001 0.001" />
      </geometry>
    </collision>
  </link>
  <joint
    name="joint_03"
    type="revolute">
    <origin
      xyz="0 0 0.00130552834300195"
      rpy="0 0 0" />
    <parent
      link="link_03" />
    <child
      link="link_04" />
    <axis
      xyz="0 1 0" />
    <limit
      lower="-0.16"
      upper="0.16"
      effort="0"
      velocity="0" />
  </joint>
  <link
    name="link_05">
    <visual>
      <origin
        xyz="0 0 0"
        rpy="0 0 0" />
      <geometry>
        <mesh
          filename="package://snake_description/meshes/link_05.STL" scale="0.001 0.001 0.001" />
      </geometry>
      <material
        name="">
        <color
          rgba="0.690196078431373 0.658823529411765 0.63921568627451 1" />
      </material>
    </visual>
    <collision>
      <origin
        xyz="0 0 0"
        rpy="0 0 0" />
      <geometry>
        <mesh
          filename="package://snake_description/meshes/link_05.STL" scale="0.001 0.001 0.001" />
      </geometry>
    </collision>
  </link>
  <joint
    name="joint_04"
    type="revolute">
    <origin
      xyz="0 0 0.00129585124582631"
      rpy="0 0 0" />
    <parent
      link="link_04" />
    <child
      link="link_05" />
    <axis
      xyz="0 1 0" />
    <limit
      lower="-0.16"
      upper="0.16"
      effort="0"
      velocity="0" />
  </joint>
  <link
    name="link_06">
    <visual>
      <origin
        xyz="0 0 0"
        rpy="0 0 0" />
      <geometry>
        <mesh
          filename="package://snake_description/meshes/link_06.STL" scale="0.001 0.001 0.001" />
      </geometry>
      <material
        name="">
        <color
          rgba="0.690196078431373 0.658823529411765 0.63921568627451 1" />
      </material>
    </visual>
    <collision>
      <origin
        xyz="0 0 0"
        rpy="0 0 0" />
      <geometry>
        <mesh
          filename="package://snake_description/meshes/link_06.STL" scale="0.001 0.001 0.001" />
      </geometry>
    </collision>
  </link>
  <joint
    name="joint_05"
    type="revolute">
    <origin
      xyz="0 0 0.00128617414865916"
      rpy="0 0 0" />
    <parent
      link="link_05" />
    <child
      link="link_06" />
    <axis
      xyz="0 1 0" />
    <limit
      lower="0"
      upper="0"
      effort="0"
      velocity="0" />
  </joint>
  <link
    name="link_07">
    <visual>
      <origin
        xyz="0 0 0"
        rpy="0 0 0" />
      <geometry>
        <mesh
          filename="package://snake_description/meshes/link_07.STL" scale="0.001 0.001 0.001" />
      </geometry>
      <material
        name="">
        <color
          rgba="0.690196078431373 0.658823529411765 0.63921568627451 1" />
      </material>
    </visual>
    <collision>
      <origin
        xyz="0 0 0"
        rpy="0 0 0" />
      <geometry>
        <mesh
          filename="package://snake_description/meshes/link_07.STL" scale="0.001 0.001 0.001" />
      </geometry>
    </collision>
  </link>
  <joint
    name="joint_06"
    type="revolute">
    <origin
      xyz="0 0 0.00127649705148352"
      rpy="0 0 0" />
    <parent
      link="link_06" />
    <child
      link="link_07" />
    <axis
      xyz="0 1 0" />
    <limit
      lower="-0.16"
      upper="0.16"
      effort="0"
      velocity="0" />
  </joint>
  <link
    name="link_08">
    <visual>
      <origin
        xyz="0 0 0"
        rpy="0 0 0" />
      <geometry>
        <mesh
          filename="package://snake_description/meshes/link_08.STL" scale="0.001 0.001 0.001" />
      </geometry>
      <material
        name="">
        <color
          rgba="0.690196078431373 0.658823529411765 0.63921568627451 1" />
      </material>
    </visual>
    <collision>
      <origin
        xyz="0 0 0"
        rpy="0 0 0" />
      <geometry>
        <mesh
          filename="package://snake_description/meshes/link_08.STL" scale="0.001 0.001 0.001" />
      </geometry>
    </collision>
  </link>
  <joint
    name="joint_07"
    type="revolute">
    <origin
      xyz="0 0 0.00126681995431425"
      rpy="0 0 0" />
    <parent
      link="link_07" />
    <child
      link="link_08" />
    <axis
      xyz="0 1 0" />
    <limit
      lower="-0.16"
      upper="0.16"
      effort="0"
      velocity="0" />
  </joint>
  <link
    name="link_09">
    <visual>
      <origin
        xyz="0 0 0"
        rpy="0 0 0" />
      <geometry>
        <mesh
          filename="package://snake_description/meshes/link_09.STL" scale="0.001 0.001 0.001" />
      </geometry>
      <material
        name="">
        <color
          rgba="0.690196078431373 0.658823529411765 0.63921568627451 1" />
      </material>
    </visual>
    <collision>
      <origin
        xyz="0 0 0"
        rpy="0 0 0" />
      <geometry>
        <mesh
          filename="package://snake_description/meshes/link_09.STL" scale="0.001 0.001 0.001" />
      </geometry>
    </collision>
  </link>
  <joint
    name="joint_08"
    type="revolute">
    <origin
      xyz="0 0 0.00125714285714286"
      rpy="0 0 0" />
    <parent
      link="link_08" />
    <child
      link="link_09" />
    <axis
      xyz="0 1 0" />
    <limit
      lower="-0.16"
      upper="0.16"
      effort="0"
      velocity="0" />
  </joint>
  <link
    name="link_10">
    <visual>
      <origin
        xyz="0 0 0"
        rpy="0 0 0" />
      <geometry>
        <mesh
          filename="package://snake_description/meshes/link_10.STL" scale="0.001 0.001 0.001" />
      </geometry>
      <material
        name="">
        <color
          rgba="0.690196078431373 0.658823529411765 0.63921568627451 1" />
      </material>
    </visual>
    <collision>
      <origin
        xyz="0 0 0"
        rpy="0 0 0" />
      <geometry>
        <mesh
          filename="package://snake_description/meshes/link_10.STL" scale="0.001 0.001 0.001" />
      </geometry>
    </collision>
  </link>
  <joint
    name="joint_09"
    type="revolute">
    <origin
      xyz="0 0 0.00124746575997359"
      rpy="0 0 0" />
    <parent
      link="link_09" />
    <child
      link="link_10" />
    <axis
      xyz="0 1 0" />
    <limit
      lower="-0.16"
      upper="0.16"
      effort="0"
      velocity="0" />
  </joint>
  <link
    name="link_11">
    <visual>
      <origin
        xyz="0 0 0"
        rpy="0 0 0" />
      <geometry>
        <mesh
          filename="package://snake_description/meshes/link_11.STL" scale="0.001 0.001 0.001" />
      </geometry>
      <material
        name="">
        <color
          rgba="0.690196078431373 0.658823529411765 0.63921568627451 1" />
      </material>
    </visual>
    <collision>
      <origin
        xyz="0 0 0"
        rpy="0 0 0" />
      <geometry>
        <mesh
          filename="package://snake_description/meshes/link_11.STL" scale="0.001 0.001 0.001" />
      </geometry>
    </collision>
  </link>
  <joint
    name="joint_10"
    type="revolute">
    <origin
      xyz="0 0 0.00123778866279794"
      rpy="0 0 0" />
    <parent
      link="link_10" />
    <child
      link="link_11" />
    <axis
      xyz="0 1 0" />
    <limit
      lower="-0.16"
      upper="0.16"
      effort="0"
      velocity="0" />
  </joint>
  <link
    name="link_12">
    <visual>
      <origin
        xyz="0 0 0"
        rpy="0 0 0" />
      <geometry>
        <mesh
          filename="package://snake_description/meshes/link_12.STL" scale="0.001 0.001 0.001" />
      </geometry>
      <material
        name="">
        <color
          rgba="0.690196078431373 0.658823529411765 0.63921568627451 1" />
      </material>
    </visual>
    <collision>
      <origin
        xyz="0 0 0"
        rpy="0 0 0" />
      <geometry>
        <mesh
          filename="package://snake_description/meshes/link_12.STL" scale="0.001 0.001 0.001" />
      </geometry>
    </collision>
  </link>
  <joint
    name="joint_11"
    type="revolute">
    <origin
      xyz="0 0 0.00122811156562867"
      rpy="0 0 0" />
    <parent
      link="link_11" />
    <child
      link="link_12" />
    <axis
      xyz="0 1 0" />
    <limit
      lower="-0.16"
      upper="0.16"
      effort="0"
      velocity="0" />
  </joint>
  <link
    name="link_13">
    <visual>
      <origin
        xyz="0 0 0"
        rpy="0 0 0" />
      <geometry>
        <mesh
          filename="package://snake_description/meshes/link_13.STL" scale="0.001 0.001 0.001" />
      </geometry>
      <material
        name="">
        <color
          rgba="0.690196078431373 0.658823529411765 0.63921568627451 1" />
      </material>
    </visual>
    <collision>
      <origin
        xyz="0 0 0"
        rpy="0 0 0" />
      <geometry>
        <mesh
          filename="package://snake_description/meshes/link_13.STL" scale="0.001 0.001 0.001" />
      </geometry>
    </collision>
  </link>
  <joint
    name="joint_12"
    type="revolute">
    <origin
      xyz="0 0 0.00121843446845728"
      rpy="0 0 0" />
    <parent
      link="link_12" />
    <child
      link="link_13" />
    <axis
      xyz="0 1 0" />
    <limit
      lower="-0.16"
      upper="0.16"
      effort="0"
      velocity="0" />
  </joint>
  <link
    name="link_14">
    <visual>
      <origin
        xyz="0 0 0"
        rpy="0 0 0" />
      <geometry>
        <mesh
          filename="package://snake_description/meshes/link_14.STL" scale="0.001 0.001 0.001" />
      </geometry>
      <material
        name="">
        <color
          rgba="0.690196078431373 0.658823529411765 0.63921568627451 1" />
      </material>
    </visual>
    <collision>
      <origin
        xyz="0 0 0"
        rpy="0 0 0" />
      <geometry>
        <mesh
          filename="package://snake_description/meshes/link_14.STL" scale="0.001 0.001 0.001" />
      </geometry>
    </collision>
  </link>
  <joint
    name="joint_13"
    type="revolute">
    <origin
      xyz="0 0 0.00120875737128587"
      rpy="0 0 0" />
    <parent
      link="link_13" />
    <child
      link="link_14" />
    <axis
      xyz="0 1 0" />
    <limit
      lower="-0.16"
      upper="0.16"
      effort="0"
      velocity="0" />
  </joint>
  <link
    name="link_15">
    <visual>
      <origin
        xyz="0 0 0"
        rpy="0 0 0" />
      <geometry>
        <mesh
          filename="package://snake_description/meshes/link_15.STL" scale="0.001 0.001 0.001" />
      </geometry>
      <material
        name="">
        <color
          rgba="0.690196078431373 0.658823529411765 0.63921568627451 1" />
      </material>
    </visual>
    <collision>
      <origin
        xyz="0 0 0"
        rpy="0 0 0" />
      <geometry>
        <mesh
          filename="package://snake_description/meshes/link_15.STL" scale="0.001 0.001 0.001" />
      </geometry>
    </collision>
  </link>
  <joint
    name="joint_14"
    type="revolute">
    <origin
      xyz="0 0 0.00119908027411451"
      rpy="0 0 0" />
    <parent
      link="link_14" />
    <child
      link="link_15" />
    <axis
      xyz="0 1 0" />
    <limit
      lower="-0.16"
      upper="0.16"
      effort="0"
      velocity="0" />
  </joint>
  <link
    name="link_16">
    <visual>
      <origin
        xyz="0 0 0"
        rpy="0 0 0" />
      <geometry>
        <mesh
          filename="package://snake_description/meshes/link_16.STL" scale="0.001 0.001 0.001" />
      </geometry>
      <material
        name="">
        <color
          rgba="0.690196078431373 0.658823529411765 0.63921568627451 1" />
      </material>
    </visual>
    <collision>
      <origin
        xyz="0 0 0"
        rpy="0 0 0" />
      <geometry>
        <mesh
          filename="package://snake_description/meshes/link_16.STL" scale="0.001 0.001 0.001" />
      </geometry>
    </collision>
  </link>
  <joint
    name="joint_15"
    type="revolute">
    <origin
      xyz="0 0 0.0011894031769431"
      rpy="0 0 0" />
    <parent
      link="link_15" />
    <child
      link="link_16" />
    <axis
      xyz="0 1 0" />
    <limit
      lower="-0.16"
      upper="0.16"
      effort="0"
      velocity="0" />
  </joint>
  <link
    name="link_17">
    <visual>
      <origin
        xyz="0 0 0"
        rpy="0 0 0" />
      <geometry>
        <mesh
          filename="package://snake_description/meshes/link_17.STL" scale="0.001 0.001 0.001" />
      </geometry>
      <material
        name="">
        <color
          rgba="0.690196078431373 0.658823529411765 0.63921568627451 1" />
      </material>
    </visual>
    <collision>
      <origin
        xyz="0 0 0"
        rpy="0 0 0" />
      <geometry>
        <mesh
          filename="package://snake_description/meshes/link_17.STL" scale="0.001 0.001 0.001" />
      </geometry>
    </collision>
  </link>
  <joint
    name="joint_16"
    type="revolute">
    <origin
      xyz="0 0 0.0011797260797717"
      rpy="0 0 0" />
    <parent
      link="link_16" />
    <child
      link="link_17" />
    <axis
      xyz="0 1 0" />
    <limit
      lower="-0.16"
      upper="0.16"
      effort="0"
      velocity="0" />
  </joint>
  <link
    name="link_18">
    <visual>
      <origin
        xyz="0 0 0"
        rpy="0 0 0" />
      <geometry>
        <mesh
          filename="package://snake_description/meshes/link_18.STL" scale="0.001 0.001 0.001" />
      </geometry>
      <material
        name="">
        <color
          rgba="0.690196078431373 0.658823529411765 0.63921568627451 1" />
      </material>
    </visual>
    <collision>
      <origin
        xyz="0 0 0"
        rpy="0 0 0" />
      <geometry>
        <mesh
          filename="package://snake_description/meshes/link_18.STL" scale="0.001 0.001 0.001" />
      </geometry>
    </collision>
  </link>
  <joint
    name="joint_17"
    type="revolute">
    <origin
      xyz="0 0 0.00117004898260031"
      rpy="0 0 0" />
    <parent
      link="link_17" />
    <child
      link="link_18" />
    <axis
      xyz="0 1 0" />
    <limit
      lower="-0.16"
      upper="0.16"
      effort="0"
      velocity="0" />
  </joint>
  <link
    name="link_19">
    <visual>
      <origin
        xyz="0 0 0"
        rpy="0 0 0" />
      <geometry>
        <mesh
          filename="package://snake_description/meshes/link_19.STL" scale="0.001 0.001 0.001" />
      </geometry>
      <material
        name="">
        <color
          rgba="0.690196078431373 0.658823529411765 0.63921568627451 1" />
      </material>
    </visual>
    <collision>
      <origin
        xyz="0 0 0"
        rpy="0 0 0" />
      <geometry>
        <mesh
          filename="package://snake_description/meshes/link_19.STL" scale="0.001 0.001 0.001" />
      </geometry>
    </collision>
  </link>
  <joint
    name="joint_18"
    type="revolute">
    <origin
      xyz="0 0 0.00116037188542892"
      rpy="0 0 0" />
    <parent
      link="link_18" />
    <child
      link="link_19" />
    <axis
      xyz="0 1 0" />
    <limit
      lower="-0.16"
      upper="0.16"
      effort="0"
      velocity="0" />
  </joint>
  <link
    name="link_20">
    <visual>
      <origin
        xyz="0 0 0"
        rpy="0 0 0" />
      <geometry>
        <mesh
          filename="package://snake_description/meshes/link_20.STL" scale="0.001 0.001 0.001" />
      </geometry>
      <material
        name="">
        <color
          rgba="0.690196078431373 0.658823529411765 0.63921568627451 1" />
      </material>
    </visual>
    <collision>
      <origin
        xyz="0 0 0"
        rpy="0 0 0" />
      <geometry>
        <mesh
          filename="package://snake_description/meshes/link_20.STL" scale="0.001 0.001 0.001" />
      </geometry>
    </collision>
  </link>
  <joint
    name="joint_19"
    type="revolute">
    <origin
      xyz="0 0 0.00115069478825752"
      rpy="0 0 0" />
    <parent
      link="link_19" />
    <child
      link="link_20" />
    <axis
      xyz="0 1 0" />
    <limit
      lower="-0.16"
      upper="0.16"
      effort="0"
      velocity="0" />
  </joint>
  <link
    name="link_21">
    <visual>
      <origin
        xyz="0 0 0"
        rpy="0 0 0" />
      <geometry>
        <mesh
          filename="package://snake_description/meshes/link_21.STL" scale="0.001 0.001 0.001" />
      </geometry>
      <material
        name="">
        <color
          rgba="0.690196078431373 0.658823529411765 0.63921568627451 1" />
      </material>
    </visual>
    <collision>
      <origin
        xyz="0 0 0"
        rpy="0 0 0" />
      <geometry>
        <mesh
          filename="package://snake_description/meshes/link_21.STL" scale="0.001 0.001 0.001" />
      </geometry>
    </collision>
  </link>
  <joint
    name="joint_20"
    type="revolute">
    <origin
      xyz="0 0 0.00114101769108614"
      rpy="0 0 0" />
    <parent
      link="link_20" />
    <child
      link="link_21" />
    <axis
      xyz="0 1 0" />
    <limit
      lower="-0.16"
      upper="0.16"
      effort="0"
      velocity="0" />
  </joint>
  <link
    name="link_22">
    <visual>
      <origin
        xyz="0 0 0"
        rpy="0 0 0" />
      <geometry>
        <mesh
          filename="package://snake_description/meshes/link_22.STL" scale="0.001 0.001 0.001" />
      </geometry>
      <material
        name="">
        <color
          rgba="0.690196078431373 0.658823529411765 0.63921568627451 1" />
      </material>
    </visual>
    <collision>
      <origin
        xyz="0 0 0"
        rpy="0 0 0" />
      <geometry>
        <mesh
          filename="package://snake_description/meshes/link_22.STL" scale="0.001 0.001 0.001" />
      </geometry>
    </collision>
  </link>
  <joint
    name="joint_21"
    type="revolute">
    <origin
      xyz="0 0 0.00113295011421438"
      rpy="0 0 0" />
    <parent
      link="link_21" />
    <child
      link="link_22" />
    <axis
      xyz="0 1 0" />
    <limit
      lower="-0.16"
      upper="0.16"
      effort="0"
      velocity="0" />
  </joint>
  <link
    name="link_23">
    <visual>
      <origin
        xyz="0 0 0"
        rpy="0 0 0" />
      <geometry>
        <mesh
          filename="package://snake_description/meshes/link_23.STL" scale="0.001 0.001 0.001" />
      </geometry>
      <material
        name="">
        <color
          rgba="0.690196078431373 0.658823529411765 0.63921568627451 1" />
      </material>
    </visual>
    <collision>
      <origin
        xyz="0 0 0"
        rpy="0 0 0" />
      <geometry>
        <mesh
          filename="package://snake_description/meshes/link_23.STL" scale="0.001 0.001 0.001" />
      </geometry>
    </collision>
  </link>
  <joint
    name="joint_22"
    type="revolute">
    <origin
      xyz="0 0 0.00112972108592831"
      rpy="0 0 0" />
    <parent
      link="link_22" />
    <child
      link="link_23" />
    <axis
      xyz="0 1 0" />
    <limit
      lower="-0.16"
      upper="0.16"
      effort="0"
      velocity="0" />
  </joint>
  <link
    name="link_24">
    <visual>
      <origin
        xyz="0 0 0"
        rpy="0 0 0" />
      <geometry>
        <mesh
          filename="package://snake_description/meshes/link_24.STL" scale="0.001 0.001 0.001" />
      </geometry>
      <material
        name="">
        <color
          rgba="0.690196078431373 0.658823529411765 0.63921568627451 1" />
      </material>
    </visual>
    <collision>
      <origin
        xyz="0 0 0"
        rpy="0 0 0" />
      <geometry>
        <mesh
          filename="package://snake_description/meshes/link_24.STL" scale="0.001 0.001 0.001" />
      </geometry>
    </collision>
  </link>
  <joint
    name="joint_23"
    type="revolute">
    <origin
      xyz="0 0 0.00112972108593046"
      rpy="0 0 0" />
    <parent
      link="link_23" />
    <child
      link="link_24" />
    <axis
      xyz="0 1 0" />
    <limit
      lower="-0.16"
      upper="0.16"
      effort="0"
      velocity="0" />
  </joint>
  <link
    name="link_25">
    <visual>
      <origin
        xyz="0 0 0"
        rpy="0 0 0" />
      <geometry>
        <mesh
          filename="package://snake_description/meshes/link_25.STL" scale="0.001 0.001 0.001" />
      </geometry>
      <material
        name="">
        <color
          rgba="0.690196078431373 0.658823529411765 0.63921568627451 1" />
      </material>
    </visual>
    <collision>
      <origin
        xyz="0 0 0"
        rpy="0 0 0" />
      <geometry>
        <mesh
          filename="package://snake_description/meshes/link_25.STL" scale="0.001 0.001 0.001" />
      </geometry>
    </collision>
  </link>
  <joint
    name="joint_24"
    type="revolute">
    <origin
      xyz="0 0 0.00112972108592616"
      rpy="0 0 0" />
    <parent
      link="link_24" />
    <child
      link="link_25" />
    <axis
      xyz="0 1 0" />
    <limit
      lower="-0.16"
      upper="0.16"
      effort="0"
      velocity="0" />
  </joint>
  <link
    name="link_26">
    <visual>
      <origin
        xyz="0 0 0"
        rpy="0 0 0" />
      <geometry>
        <mesh
          filename="package://snake_description/meshes/link_26.STL" scale="0.001 0.001 0.001" />
      </geometry>
      <material
        name="">
        <color
          rgba="0.690196078431373 0.658823529411765 0.63921568627451 1" />
      </material>
    </visual>
    <collision>
      <origin
        xyz="0 0 0"
        rpy="0 0 0" />
      <geometry>
        <mesh
          filename="package://snake_description/meshes/link_26.STL" scale="0.001 0.001 0.001" />
      </geometry>
    </collision>
  </link>
  <joint
    name="joint_25"
    type="revolute">
    <origin
      xyz="0 0 0.00112972108592835"
      rpy="0 0 0" />
    <parent
      link="link_25" />
    <child
      link="link_26" />
    <axis
      xyz="0 1 0" />
    <limit
      lower="-0.16"
      upper="0.16"
      effort="0"
      velocity="0" />
  </joint>
  <link
    name="link_27">
    <visual>
      <origin
        xyz="0 0 0"
        rpy="0 0 0" />
      <geometry>
        <mesh
          filename="package://snake_description/meshes/link_27.STL" scale="0.001 0.001 0.001" />
      </geometry>
      <material
        name="">
        <color
          rgba="0.690196078431373 0.658823529411765 0.63921568627451 1" />
      </material>
    </visual>
    <collision>
      <origin
        xyz="0 0 0"
        rpy="0 0 0" />
      <geometry>
        <mesh
          filename="package://snake_description/meshes/link_27.STL" scale="0.001 0.001 0.001" />
      </geometry>
    </collision>
  </link>
  <joint
    name="joint_26"
    type="revolute">
    <origin
      xyz="0 0 0.00112972108592829"
      rpy="0 0 0" />
    <parent
      link="link_26" />
    <child
      link="link_27" />
    <axis
      xyz="0 1 0" />
    <limit
      lower="-0.16"
      upper="0.16"
      effort="0"
      velocity="0" />
  </joint>
  <link name="link_ee" />
  <joint
    name="joint_27"
    type="fixed">
    <origin
      xyz="0 0 0.0025297210859283"
      rpy="0 0 0" />
    <parent
      link="link_27" />
    <child
      link="link_ee" />
    <axis
      xyz="0 0 0" />
  </joint>
</robot>
